{
    "registryname": "advanced_matter_extractor",
    "localizedname": "Advanced Matter Extractor",
	 "modifiers": [
        {
            "elements": ["overloaded:compressed_cobblestone@0","overloaded:compressed_sand@0","overloaded:compressed_stone@0","overloaded:compressed_obsidian@0","overloaded:compressed_netherrack@0","overloaded:compressed_dirt@0","overloaded:compressed_gravel@0"],
            "x": 0,
            "y": -3,
            "z": 0,
            "description": "Replace the centre block with a compressed block. The higher the hardness factor, the more efficient the extraction.",
			"modifier": [
				{
				"target": "modularmachinery:duration",
                "io": "output",
                "operation": 1,
				"multiplier": 65536.0
				},
				{
				"target": "modularmachinery:energy",
                "io": "output",
                "operation": 1,
				"multiplier": 65536.0
				}
			]
        },
        {
            "elements": ["overloaded:compressed_cobblestone@1","overloaded:compressed_sand@1","overloaded:compressed_stone@1","overloaded:compressed_obsidian@1","overloaded:compressed_netherrack@1","overloaded:compressed_dirt@1","overloaded:compressed_gravel@1"],
            "x": 0,
            "y": -3,
            "z": 0,
            "description": "Replace the centre block with a compressed block. The higher the hardness factor, the more efficient the extraction.",
			"modifier": [
				{
				"target": "modularmachinery:duration",
                "io": "output",
                "operation": 1,
				"multiplier": 32768.0
				},
				{
				"target": "modularmachinery:energy",
                "io": "output",
                "operation": 1,
				"multiplier": 32768.0
				}
			]
        },
        {
            "elements": ["overloaded:compressed_cobblestone@2","overloaded:compressed_sand@2","overloaded:compressed_stone@2","overloaded:compressed_obsidian@2","overloaded:compressed_netherrack@2","overloaded:compressed_dirt@2","overloaded:compressed_gravel@2"],
            "x": 0,
            "y": -3,
            "z": 0,
            "description": "Replace the centre block with a compressed block. The higher the hardness factor, the more efficient the extraction.",
			"modifier": [
				{
				"target": "modularmachinery:duration",
                "io": "output",
                "operation": 1,
				"multiplier": 16384.0
				},
				{
				"target": "modularmachinery:energy",
                "io": "output",
                "operation": 1,
				"multiplier": 16384.0
				}
			]
        },
        {
            "elements": ["overloaded:compressed_cobblestone@3","overloaded:compressed_sand@3","overloaded:compressed_stone@3","overloaded:compressed_obsidian@3","overloaded:compressed_netherrack@3","overloaded:compressed_dirt@3","overloaded:compressed_gravel@3"],
            "x": 0,
            "y": -3,
            "z": 0,
            "description": "Replace the centre block with a compressed block. The higher the hardness factor, the more efficient the extraction.",
			"modifier": [
				{
				"target": "modularmachinery:duration",
                "io": "output",
                "operation": 1,
				"multiplier": 8192.0
				},
				{
				"target": "modularmachinery:energy",
                "io": "output",
                "operation": 1,
				"multiplier": 8192.0
				}
			]
        },
        {
            "elements": ["overloaded:compressed_cobblestone@4","overloaded:compressed_sand@4","overloaded:compressed_stone@4","overloaded:compressed_obsidian@4","overloaded:compressed_netherrack@4","overloaded:compressed_dirt@4","overloaded:compressed_gravel@4"],
            "x": 0,
            "y": -3,
            "z": 0,
            "description": "Replace the centre block with a compressed block. The higher the hardness factor, the more efficient the extraction.",
			"modifier": [
				{
				"target": "modularmachinery:duration",
                "io": "output",
                "operation": 1,
				"multiplier": 4096.0
				},
				{
				"target": "modularmachinery:energy",
                "io": "output",
                "operation": 1,
				"multiplier": 4096.0
				}
			]
        },
        {
            "elements": ["overloaded:compressed_cobblestone@5","overloaded:compressed_sand@5","overloaded:compressed_stone@5","overloaded:compressed_obsidian@5","overloaded:compressed_netherrack@5","overloaded:compressed_dirt@5","overloaded:compressed_gravel@5"],
            "x": 0,
            "y": -3,
            "z": 0,
            "description": "Replace the centre block with a compressed block. The higher the hardness factor, the more efficient the extraction.",
			"modifier": [
				{
				"target": "modularmachinery:duration",
                "io": "output",
                "operation": 1,
				"multiplier": 2048.0
				},
				{
				"target": "modularmachinery:energy",
                "io": "output",
                "operation": 1,
				"multiplier": 2048.0
				}
			]
        },
        {
            "elements": ["overloaded:compressed_cobblestone@6","overloaded:compressed_sand@6","overloaded:compressed_stone@6","overloaded:compressed_obsidian@6","overloaded:compressed_netherrack@6","overloaded:compressed_dirt@6","overloaded:compressed_gravel@6"],
            "x": 0,
            "y": -3,
            "z": 0,
            "description": "Replace the centre block with a compressed block. The higher the hardness factor, the more efficient the extraction.",
			"modifier": [
				{
				"target": "modularmachinery:duration",
                "io": "output",
                "operation": 1,
				"multiplier": 1024.0
				},
				{
				"target": "modularmachinery:energy",
                "io": "output",
                "operation": 1,
				"multiplier": 1024.0
				}
			]
        },
        {
            "elements": ["overloaded:compressed_cobblestone@7","overloaded:compressed_sand@7","overloaded:compressed_stone@7","overloaded:compressed_obsidian@7","overloaded:compressed_netherrack@7","overloaded:compressed_dirt@7","overloaded:compressed_gravel@7"],
            "x": 0,
            "y": -3,
            "z": 0,
            "description": "Replace the centre block with a compressed block. The higher the hardness factor, the more efficient the extraction.",
			"modifier": [
				{
				"target": "modularmachinery:duration",
                "io": "output",
                "operation": 1,
				"multiplier": 512.0
				},
				{
				"target": "modularmachinery:energy",
                "io": "output",
                "operation": 1,
				"multiplier": 512.0
				}
			]
        },
        {
            "elements": ["overloaded:compressed_cobblestone@8","overloaded:compressed_sand@8","overloaded:compressed_stone@8","overloaded:compressed_obsidian@8","overloaded:compressed_netherrack@8","overloaded:compressed_dirt@8","overloaded:compressed_gravel@8"],
            "x": 0,
            "y": -3,
            "z": 0,
            "description": "Replace the centre block with a compressed block. The higher the hardness factor, the more efficient the extraction.",
			"modifier": [
				{
				"target": "modularmachinery:duration",
                "io": "output",
                "operation": 1,
				"multiplier": 256.0
				},
				{
				"target": "modularmachinery:energy",
                "io": "output",
                "operation": 1,
				"multiplier": 256.0
				}
			]
        },
        {
            "elements": ["overloaded:compressed_cobblestone@9","overloaded:compressed_sand@9","overloaded:compressed_stone@9","overloaded:compressed_obsidian@9","overloaded:compressed_netherrack@9","overloaded:compressed_dirt@9","overloaded:compressed_gravel@9"],
            "x": 0,
            "y": -3,
            "z": 0,
            "description": "Replace the centre block with a compressed block. The higher the hardness factor, the more efficient the extraction.",
			"modifier": [
				{
				"target": "modularmachinery:duration",
                "io": "output",
                "operation": 1,
				"multiplier": 128.0
				},
				{
				"target": "modularmachinery:energy",
                "io": "output",
                "operation": 1,
				"multiplier": 128.0
				}
			]
        },
        {
            "elements": ["overloaded:compressed_cobblestone@10","overloaded:compressed_sand@10","overloaded:compressed_stone@10","overloaded:compressed_obsidian@10","overloaded:compressed_netherrack@10","overloaded:compressed_dirt@10","overloaded:compressed_gravel@10"],
            "x": 0,
            "y": -3,
            "z": 0,
            "description": "Replace the centre block with a compressed block. The higher the hardness factor, the more efficient the extraction.",
			"modifier": [
				{
				"target": "modularmachinery:duration",
                "io": "output",
                "operation": 1,
				"multiplier": 64.0
				},
				{
				"target": "modularmachinery:energy",
                "io": "output",
                "operation": 1,
				"multiplier": 64.0
				}
			]
        },
        {
            "elements": ["overloaded:compressed_cobblestone@11","overloaded:compressed_sand@11","overloaded:compressed_stone@11","overloaded:compressed_obsidian@11","overloaded:compressed_netherrack@11","overloaded:compressed_dirt@11","overloaded:compressed_gravel@11"],
            "x": 0,
            "y": -3,
            "z": 0,
            "description": "Replace the centre block with a compressed block. The higher the hardness factor, the more efficient the extraction.",
			"modifier": [
				{
				"target": "modularmachinery:duration",
                "io": "output",
                "operation": 1,
				"multiplier": 32.0
				},
				{
				"target": "modularmachinery:energy",
                "io": "output",
                "operation": 1,
				"multiplier": 32.0
				}
			]
        },
        {
            "elements": ["overloaded:compressed_cobblestone@12","overloaded:compressed_sand@12","overloaded:compressed_stone@12","overloaded:compressed_obsidian@12","overloaded:compressed_netherrack@12","overloaded:compressed_dirt@12","overloaded:compressed_gravel@12"],
            "x": 0,
            "y": -3,
            "z": 0,
            "description": "Replace the centre block with a compressed block. The higher the hardness factor, the more efficient the extraction.",
			"modifier": [
				{
				"target": "modularmachinery:duration",
                "io": "output",
                "operation": 1,
				"multiplier": 16.0
				},
				{
				"target": "modularmachinery:energy",
                "io": "output",
                "operation": 1,
				"multiplier": 16.0
				}
			]
        },
        {
            "elements": ["overloaded:compressed_cobblestone@13","overloaded:compressed_sand@13","overloaded:compressed_stone@13","overloaded:compressed_obsidian@13","overloaded:compressed_netherrack@13","overloaded:compressed_dirt@13","overloaded:compressed_gravel@13"],
            "x": 0,
            "y": -3,
            "z": 0,
            "description": "Replace the centre block with a compressed block. The higher the hardness factor, the more efficient the extraction.",
			"modifier": [
				{
				"target": "modularmachinery:duration",
                "io": "output",
                "operation": 1,
				"multiplier": 8.0
				},
				{
				"target": "modularmachinery:energy",
                "io": "output",
                "operation": 1,
				"multiplier": 8.0
				}
			]
        },
        {
            "elements": ["overloaded:compressed_cobblestone@14","overloaded:compressed_sand@14","overloaded:compressed_stone@14","overloaded:compressed_obsidian@14","overloaded:compressed_netherrack@14","overloaded:compressed_dirt@14","overloaded:compressed_gravel@14"],
            "x": 0,
            "y": -3,
            "z": 0,
            "description": "Replace the centre block with a compressed block. The higher the hardness factor, the more efficient the extraction.",
			"modifier": [
				{
				"target": "modularmachinery:duration",
                "io": "output",
                "operation": 1,
				"multiplier": 4.0
				},
				{
				"target": "modularmachinery:energy",
                "io": "output",
                "operation": 1,
				"multiplier": 4.0
				}
			]
        }
    ],
    "parts": [
        {
            "x": -3,
            "y": -4,
            "z": -2,
            "elements": [
                "quark:iron_plate@0"
            ]
        },
        {
            "x": -2,
            "y": -2,
            "z": -1,
            "elements": [
                "thermalfoundation:fluid_aerotheum@0"
            ]
        },
        {
            "x": -1,
            "y": 0,
            "z": 0,
            "elements": [
                "immersiveengineering:sheetmetal@8"
            ]
        },
        {
            "x": -3,
            "y": -2,
            "z": -1,
            "elements": [
                "immersiveengineering:sheetmetal@8"
            ]
        },
        {
            "x": -2,
            "y": 0,
            "z": 0,
            "elements": [
                "immersiveengineering:sheetmetal@8"
            ]
        },
        {
            "x": 1,
            "y": 0,
            "z": 0,
            "elements": [
                "immersiveengineering:sheetmetal@8"
            ]
        },
        {
            "x": -3,
            "y": 0,
            "z": 0,
            "elements": [
                "quark:iron_plate_stairs@0"
            ]
        },
        {
            "x": 2,
            "y": 0,
            "z": 0,
            "elements": [
                "immersiveengineering:sheetmetal@8"
            ]
        },
        {
            "x": 3,
            "y": 0,
            "z": 0,
            "elements": [
                "quark:iron_plate_stairs@1"
            ]
        },
        {
            "x": 3,
            "y": -5,
            "z": -2,
            "elements": [
                "quark:iron_plate@0"
            ]
        },
        {
            "x": 2,
            "y": -5,
            "z": -2,
            "elements": [
                "thermalfoundation:glass@8"
            ]
        },
        {
            "x": 3,
            "y": -3,
            "z": -1,
            "elements": [
                "immersiveengineering:sheetmetal@8"
            ]
        },
        {
            "x": 1,
            "y": -5,
            "z": -2,
            "elements": [
                "thermalfoundation:glass@8"
            ]
        },
        {
            "x": 2,
            "y": -3,
            "z": -1,
            "elements": [
                "thermalfoundation:fluid_aerotheum@0"
            ]
        },
        {
            "x": 3,
            "y": -1,
            "z": 0,
            "elements": [
                "immersiveengineering:sheetmetal@8"
            ]
        },
        {
            "x": 0,
            "y": -5,
            "z": -2,
            "elements": [
                "thermalfoundation:glass@8"
            ]
        },
        {
            "x": 1,
            "y": -3,
            "z": -1,
            "elements": [
                "thermalfoundation:fluid_aerotheum@0"
            ]
        },
        {
            "x": 2,
            "y": -1,
            "z": 0,
            "elements": [
                "thermalfoundation:fluid_aerotheum@0"
            ]
        },
        {
            "x": -1,
            "y": -5,
            "z": -2,
            "elements": [
                "thermalfoundation:glass@8"
            ]
        },
        {
            "x": 0,
            "y": -3,
            "z": -1,
            "elements": [
                "thermalfoundation:fluid_aerotheum@0"
            ]
        },
        {
            "x": 1,
            "y": -1,
            "z": 0,
            "elements": [
                "thermalfoundation:fluid_aerotheum@0"
            ]
        },
        {
            "x": -2,
            "y": -5,
            "z": -2,
            "elements": [
                "thermalfoundation:glass@8"
            ]
        },
        {
            "x": -1,
            "y": -3,
            "z": -1,
            "elements": [
                "thermalfoundation:fluid_aerotheum@0"
            ]
        },
        {
            "x": 0,
            "y": -1,
            "z": 0,
            "elements": [
                "thermaldynamics:duct_64@0"
            ]
        },
        {
            "x": -3,
            "y": -5,
            "z": -2,
            "elements": [
                "quark:iron_plate@0"
            ]
        },
        {
            "x": -2,
            "y": -3,
            "z": -1,
            "elements": [
                "thermalfoundation:fluid_aerotheum@0"
            ]
        },
        {
            "x": -1,
            "y": -1,
            "z": 0,
            "elements": [
                "thermalfoundation:fluid_aerotheum@0"
            ]
        },
        {
            "x": -3,
            "y": -3,
            "z": -1,
            "elements": [
                "immersiveengineering:sheetmetal@8"
            ]
        },
        {
            "x": -2,
            "y": -1,
            "z": 0,
            "elements": [
                "thermalfoundation:fluid_aerotheum@0"
            ]
        },
        {
            "x": -3,
            "y": -1,
            "z": 0,
            "elements": [
                "immersiveengineering:sheetmetal@8"
            ]
        },
        {
            "x": 3,
            "y": -6,
            "z": -2,
            "elements": [
                "quark:iron_plate_stairs@5"
            ]
        },
        {
            "x": 2,
            "y": -6,
            "z": -2,
            "elements": [
                "quark:iron_plate@0"
            ]
        },
        {
            "x": 3,
            "y": -4,
            "z": -1,
            "elements": [
                "immersiveengineering:sheetmetal@8"
            ]
        },
        {
            "x": 1,
            "y": -6,
            "z": -2,
            "elements": [
                "quark:iron_plate@0"
            ]
        },
        {
            "x": 2,
            "y": -4,
            "z": -1,
            "elements": [
                "thermalfoundation:fluid_aerotheum@0"
            ]
        },
        {
            "x": 3,
            "y": -2,
            "z": 0,
            "elements": [
                "immersiveengineering:sheetmetal@8"
            ]
        },
        {
            "x": 0,
            "y": -6,
            "z": -2,
            "elements": [
                "quark:iron_plate@0"
            ]
        },
        {
            "x": 1,
            "y": -4,
            "z": -1,
            "elements": [
                "thermalfoundation:fluid_aerotheum@0"
            ]
        },
        {
            "x": 2,
            "y": -2,
            "z": 0,
            "elements": [
                "thermalfoundation:fluid_aerotheum@0"
            ]
        },
        {
            "x": -1,
            "y": -6,
            "z": -2,
            "elements": [
                "quark:iron_plate@0"
            ]
        },
        {
            "x": 0,
            "y": -4,
            "z": -1,
            "elements": [
                "thermalfoundation:fluid_aerotheum@0"
            ]
        },
        {
            "x": 1,
            "y": -2,
            "z": 0,
            "elements": [
                "thermalfoundation:fluid_aerotheum@0"
            ]
        },
        {
            "x": -2,
            "y": -6,
            "z": -2,
            "elements": [
                "quark:iron_plate@0"
            ]
        },
        {
            "x": -1,
            "y": -4,
            "z": -1,
            "elements": [
                "thermalfoundation:fluid_aerotheum@0"
            ]
        },
        {
            "x": 0,
            "y": -2,
            "z": 0,
            "elements": [
                "thermaldynamics:duct_64@0"
            ]
        },
        {
            "x": -3,
            "y": -6,
            "z": -2,
            "elements": [
                "quark:iron_plate_stairs@4"
            ]
        },
        {
            "x": -2,
            "y": -4,
            "z": -1,
            "elements": [
                "thermalfoundation:fluid_aerotheum@0"
            ]
        },
        {
            "x": -1,
            "y": -2,
            "z": 0,
            "elements": [
                "thermalfoundation:fluid_aerotheum@0"
            ]
        },
        {
            "x": -3,
            "y": -4,
            "z": -1,
            "elements": [
                "immersiveengineering:sheetmetal@8"
            ]
        },
        {
            "x": -2,
            "y": -2,
            "z": 0,
            "elements": [
                "thermalfoundation:fluid_aerotheum@0"
            ]
        },
        {
            "x": -3,
            "y": -2,
            "z": 0,
            "elements": [
                "immersiveengineering:sheetmetal@8"
            ]
        },
        {
            "x": 3,
            "y": -5,
            "z": -1,
            "elements": [
                "immersiveengineering:sheetmetal@8"
            ]
        },
        {
            "x": 2,
            "y": -5,
            "z": -1,
            "elements": [
                "thermalfoundation:fluid_aerotheum@0"
            ]
        },
        {
            "x": 3,
            "y": -3,
            "z": 0,
            "elements": "modularmachinery:blockfluidoutputhatch"
        },
        {
            "x": 1,
            "y": -5,
            "z": -1,
            "elements": [
                "thermalfoundation:fluid_aerotheum@0"
            ]
        },
        {
            "x": 2,
            "y": -3,
            "z": 0,
            "elements": [
                "thermaldynamics:duct_64@0"
            ]
        },
        {
            "x": 0,
            "y": -5,
            "z": -1,
            "elements": [
                "thermalfoundation:fluid_aerotheum@0"
            ]
        },
        {
            "x": 1,
            "y": -3,
            "z": 0,
            "elements": [
                "thermaldynamics:duct_64@0"
            ]
        },
        {
            "x": -1,
            "y": -5,
            "z": -1,
            "elements": [
                "thermalfoundation:fluid_aerotheum@0"
            ]
        },
        {
            "x": 0,
            "y": -3,
            "z": 0,
            "elements": ["overloaded:compressed_cobblestone@15","overloaded:compressed_sand@15","overloaded:compressed_stone@15","overloaded:compressed_obsidian@15","overloaded:compressed_netherrack@15","overloaded:compressed_dirt@15","overloaded:compressed_gravel@15"]
        },
        {
            "x": -2,
            "y": -5,
            "z": -1,
            "elements": [
                "thermalfoundation:fluid_aerotheum@0"
            ]
        },
        {
            "x": -1,
            "y": -3,
            "z": 0,
            "elements": [
                "thermaldynamics:duct_64@0"
            ]
        },
        {
            "x": -3,
            "y": -5,
            "z": -1,
            "elements": [
                "immersiveengineering:sheetmetal@8"
            ]
        },
        {
            "x": -2,
            "y": -3,
            "z": 0,
            "elements": [
                "thermaldynamics:duct_64@0"
            ]
        },
        {
            "x": -3,
            "y": -3,
            "z": 0,
            "elements": "modularmachinery:blockfluidinputhatch"
        },
        {
            "x": 3,
            "y": -6,
            "z": -1,
            "elements": [
                "quark:iron_plate_stairs@5"
            ]
        },
        {
            "x": 2,
            "y": -6,
            "z": -1,
            "elements": [
                "immersiveengineering:sheetmetal@8"
            ]
        },
        {
            "x": 3,
            "y": -4,
            "z": 0,
            "elements": [
                "immersiveengineering:sheetmetal@8"
            ]
        },
        {
            "x": 1,
            "y": -6,
            "z": -1,
            "elements": [
                "immersiveengineering:sheetmetal@8"
            ]
        },
        {
            "x": 2,
            "y": -4,
            "z": 0,
            "elements": [
                "thermalfoundation:fluid_aerotheum@0"
            ]
        },
        {
            "x": 0,
            "y": -6,
            "z": -1,
            "elements": [
                "immersiveengineering:sheetmetal@8"
            ]
        },
        {
            "x": 1,
            "y": -4,
            "z": 0,
            "elements": [
                "thermalfoundation:fluid_aerotheum@0"
            ]
        },
        {
            "x": -1,
            "y": -6,
            "z": -1,
            "elements": [
                "immersiveengineering:sheetmetal@8"
            ]
        },
        {
            "x": 0,
            "y": -4,
            "z": 0,
            "elements": [
                "thermaldynamics:duct_64@0"
            ]
        },
        {
            "x": -2,
            "y": -6,
            "z": -1,
            "elements": [
                "immersiveengineering:sheetmetal@8"
            ]
        },
        {
            "x": -1,
            "y": -4,
            "z": 0,
            "elements": [
                "thermalfoundation:fluid_aerotheum@0"
            ]
        },
        {
            "x": -3,
            "y": -6,
            "z": -1,
            "elements": [
                "quark:iron_plate_stairs@4"
            ]
        },
        {
            "x": -2,
            "y": -4,
            "z": 0,
            "elements": [
                "thermalfoundation:fluid_aerotheum@0"
            ]
        },
        {
            "x": -3,
            "y": -4,
            "z": 0,
            "elements": [
                "immersiveengineering:sheetmetal@8"
            ]
        },
        {
            "x": 3,
            "y": -5,
            "z": 0,
            "elements": [
                "immersiveengineering:sheetmetal@8"
            ]
        },
        {
            "x": 2,
            "y": -5,
            "z": 0,
            "elements": [
                "thermalfoundation:fluid_aerotheum@0"
            ]
        },
        {
            "x": 1,
            "y": -5,
            "z": 0,
            "elements": [
                "thermalfoundation:fluid_aerotheum@0"
            ]
        },
        {
            "x": 0,
            "y": -5,
            "z": 0,
            "elements": [
                "thermaldynamics:duct_64@0"
            ]
        },
        {
            "x": -1,
            "y": -5,
            "z": 0,
            "elements": [
                "thermalfoundation:fluid_aerotheum@0"
            ]
        },
        {
            "x": -2,
            "y": -5,
            "z": 0,
            "elements": [
                "thermalfoundation:fluid_aerotheum@0"
            ]
        },
        {
            "x": -3,
            "y": -5,
            "z": 0,
            "elements": [
                "immersiveengineering:sheetmetal@8"
            ]
        },
        {
            "x": 3,
            "y": -6,
            "z": 0,
            "elements": [
                "quark:iron_plate_stairs@5"
            ]
        },
        {
            "x": 2,
            "y": -6,
            "z": 0,
            "elements": [
                "immersiveengineering:sheetmetal@8"
            ]
        },
        {
            "x": 1,
            "y": -6,
            "z": 0,
            "elements": [
                "immersiveengineering:sheetmetal@8"
            ]
        },
        {
            "x": 0,
            "y": -6,
            "z": 0,
            "elements": "modularmachinery:blockenergyinputhatch"
        },
        {
            "x": -1,
            "y": -6,
            "z": 0,
            "elements": [
                "immersiveengineering:sheetmetal@8"
            ]
        },
        {
            "x": -2,
            "y": -6,
            "z": 0,
            "elements": [
                "immersiveengineering:sheetmetal@8"
            ]
        },
        {
            "x": -3,
            "y": -6,
            "z": 0,
            "elements": [
                "quark:iron_plate_stairs@4"
            ]
        },
        {
            "x": -3,
            "y": -6,
            "z": 2,
            "elements": [
                "quark:iron_plate_stairs@4"
            ]
        },
        {
            "x": -2,
            "y": -6,
            "z": 2,
            "elements": [
                "quark:iron_plate@0"
            ]
        },
        {
            "x": -1,
            "y": -6,
            "z": 2,
            "elements": [
                "quark:iron_plate@0"
            ]
        },
        {
            "x": 0,
            "y": -6,
            "z": 2,
            "elements": [
                "quark:iron_plate@0"
            ]
        },
        {
            "x": 1,
            "y": -6,
            "z": 2,
            "elements": [
                "quark:iron_plate@0"
            ]
        },
        {
            "x": 2,
            "y": -6,
            "z": 2,
            "elements": [
                "quark:iron_plate@0"
            ]
        },
        {
            "x": 3,
            "y": -6,
            "z": 2,
            "elements": [
                "quark:iron_plate_stairs@5"
            ]
        },
        {
            "x": -3,
            "y": -5,
            "z": 2,
            "elements": [
                "quark:iron_plate@0"
            ]
        },
        {
            "x": -2,
            "y": -5,
            "z": 2,
            "elements": [
                "thermalfoundation:glass@8"
            ]
        },
        {
            "x": -1,
            "y": -5,
            "z": 2,
            "elements": [
                "thermalfoundation:glass@8"
            ]
        },
        {
            "x": 0,
            "y": -5,
            "z": 2,
            "elements": [
                "thermalfoundation:glass@8"
            ]
        },
        {
            "x": 1,
            "y": -5,
            "z": 2,
            "elements": [
                "thermalfoundation:glass@8"
            ]
        },
        {
            "x": 2,
            "y": -5,
            "z": 2,
            "elements": [
                "thermalfoundation:glass@8"
            ]
        },
        {
            "x": 3,
            "y": -5,
            "z": 2,
            "elements": [
                "quark:iron_plate@0"
            ]
        },
        {
            "x": -3,
            "y": -4,
            "z": 2,
            "elements": [
                "quark:iron_plate@0"
            ]
        },
        {
            "x": -3,
            "y": -6,
            "z": 1,
            "elements": [
                "quark:iron_plate_stairs@4"
            ]
        },
        {
            "x": -2,
            "y": -4,
            "z": 2,
            "elements": [
                "thermalfoundation:glass@8"
            ]
        },
        {
            "x": -2,
            "y": -6,
            "z": 1,
            "elements": [
                "immersiveengineering:sheetmetal@8"
            ]
        },
        {
            "x": -1,
            "y": -4,
            "z": 2,
            "elements": [
                "thermalfoundation:glass@8"
            ]
        },
        {
            "x": -1,
            "y": -6,
            "z": 1,
            "elements": [
                "immersiveengineering:sheetmetal@8"
            ]
        },
        {
            "x": 0,
            "y": -4,
            "z": 2,
            "elements": [
                "thermalfoundation:glass@8"
            ]
        },
        {
            "x": 0,
            "y": -6,
            "z": 1,
            "elements": [
                "immersiveengineering:sheetmetal@8"
            ]
        },
        {
            "x": 1,
            "y": -4,
            "z": 2,
            "elements": [
                "thermalfoundation:glass@8"
            ]
        },
        {
            "x": 1,
            "y": -6,
            "z": 1,
            "elements": [
                "immersiveengineering:sheetmetal@8"
            ]
        },
        {
            "x": 2,
            "y": -4,
            "z": 2,
            "elements": [
                "thermalfoundation:glass@8"
            ]
        },
        {
            "x": 2,
            "y": -6,
            "z": 1,
            "elements": [
                "immersiveengineering:sheetmetal@8"
            ]
        },
        {
            "x": 3,
            "y": -4,
            "z": 2,
            "elements": [
                "quark:iron_plate@0"
            ]
        },
        {
            "x": 3,
            "y": -6,
            "z": 1,
            "elements": [
                "quark:iron_plate_stairs@5"
            ]
        },
        {
            "x": -3,
            "y": -3,
            "z": 2,
            "elements": [
                "quark:iron_plate@0"
            ]
        },
        {
            "x": -3,
            "y": -5,
            "z": 1,
            "elements": [
                "immersiveengineering:sheetmetal@8"
            ]
        },
        {
            "x": -2,
            "y": -3,
            "z": 2,
            "elements": [
                "thermalfoundation:glass@8"
            ]
        },
        {
            "x": -2,
            "y": -5,
            "z": 1,
            "elements": [
                "thermalfoundation:fluid_aerotheum@0"
            ]
        },
        {
            "x": -1,
            "y": -3,
            "z": 2,
            "elements": [
                "thermalfoundation:glass@8"
            ]
        },
        {
            "x": -1,
            "y": -5,
            "z": 1,
            "elements": [
                "thermalfoundation:fluid_aerotheum@0"
            ]
        },
        {
            "x": 0,
            "y": -3,
            "z": 2,
            "elements": [
                "thermalfoundation:glass@8"
            ]
        },
        {
            "x": 0,
            "y": -5,
            "z": 1,
            "elements": [
                "thermalfoundation:fluid_aerotheum@0"
            ]
        },
        {
            "x": 1,
            "y": -3,
            "z": 2,
            "elements": [
                "thermalfoundation:glass@8"
            ]
        },
        {
            "x": 1,
            "y": -5,
            "z": 1,
            "elements": [
                "thermalfoundation:fluid_aerotheum@0"
            ]
        },
        {
            "x": 2,
            "y": -3,
            "z": 2,
            "elements": [
                "thermalfoundation:glass@8"
            ]
        },
        {
            "x": 2,
            "y": -5,
            "z": 1,
            "elements": [
                "thermalfoundation:fluid_aerotheum@0"
            ]
        },
        {
            "x": 3,
            "y": -3,
            "z": 2,
            "elements": [
                "quark:iron_plate@0"
            ]
        },
        {
            "x": 3,
            "y": -5,
            "z": 1,
            "elements": [
                "immersiveengineering:sheetmetal@8"
            ]
        },
        {
            "x": -3,
            "y": -2,
            "z": 2,
            "elements": [
                "quark:iron_plate@0"
            ]
        },
        {
            "x": -3,
            "y": -4,
            "z": 1,
            "elements": [
                "immersiveengineering:sheetmetal@8"
            ]
        },
        {
            "x": -2,
            "y": -2,
            "z": 2,
            "elements": [
                "thermalfoundation:glass@8"
            ]
        },
        {
            "x": -2,
            "y": -4,
            "z": 1,
            "elements": [
                "thermalfoundation:fluid_aerotheum@0"
            ]
        },
        {
            "x": -1,
            "y": -2,
            "z": 2,
            "elements": [
                "thermalfoundation:glass@8"
            ]
        },
        {
            "x": -1,
            "y": -4,
            "z": 1,
            "elements": [
                "thermalfoundation:fluid_aerotheum@0"
            ]
        },
        {
            "x": 0,
            "y": -2,
            "z": 2,
            "elements": [
                "thermalfoundation:glass@8"
            ]
        },
        {
            "x": 0,
            "y": -4,
            "z": 1,
            "elements": [
                "thermalfoundation:fluid_aerotheum@0"
            ]
        },
        {
            "x": 1,
            "y": -2,
            "z": 2,
            "elements": [
                "thermalfoundation:glass@8"
            ]
        },
        {
            "x": 1,
            "y": -4,
            "z": 1,
            "elements": [
                "thermalfoundation:fluid_aerotheum@0"
            ]
        },
        {
            "x": 2,
            "y": -2,
            "z": 2,
            "elements": [
                "thermalfoundation:glass@8"
            ]
        },
        {
            "x": 2,
            "y": -4,
            "z": 1,
            "elements": [
                "thermalfoundation:fluid_aerotheum@0"
            ]
        },
        {
            "x": 3,
            "y": -2,
            "z": 2,
            "elements": [
                "quark:iron_plate@0"
            ]
        },
        {
            "x": 3,
            "y": -4,
            "z": 1,
            "elements": [
                "immersiveengineering:sheetmetal@8"
            ]
        },
        {
            "x": -3,
            "y": -1,
            "z": 2,
            "elements": [
                "quark:iron_plate@0"
            ]
        },
        {
            "x": -3,
            "y": -3,
            "z": 1,
            "elements": [
                "immersiveengineering:sheetmetal@8"
            ]
        },
        {
            "x": -2,
            "y": -1,
            "z": 2,
            "elements": [
                "thermalfoundation:glass@8"
            ]
        },
        {
            "x": -2,
            "y": -3,
            "z": 1,
            "elements": [
                "thermalfoundation:fluid_aerotheum@0"
            ]
        },
        {
            "x": -1,
            "y": -1,
            "z": 2,
            "elements": [
                "thermalfoundation:glass@8"
            ]
        },
        {
            "x": -1,
            "y": -3,
            "z": 1,
            "elements": [
                "thermalfoundation:fluid_aerotheum@0"
            ]
        },
        {
            "x": 0,
            "y": -1,
            "z": 2,
            "elements": [
                "thermalfoundation:glass@8"
            ]
        },
        {
            "x": 0,
            "y": -3,
            "z": 1,
            "elements": [
                "thermalfoundation:fluid_aerotheum@0"
            ]
        },
        {
            "x": 1,
            "y": -1,
            "z": 2,
            "elements": [
                "thermalfoundation:glass@8"
            ]
        },
        {
            "x": 1,
            "y": -3,
            "z": 1,
            "elements": [
                "thermalfoundation:fluid_aerotheum@0"
            ]
        },
        {
            "x": 2,
            "y": -1,
            "z": 2,
            "elements": [
                "thermalfoundation:glass@8"
            ]
        },
        {
            "x": 2,
            "y": -3,
            "z": 1,
            "elements": [
                "thermalfoundation:fluid_aerotheum@0"
            ]
        },
        {
            "x": 3,
            "y": -1,
            "z": 2,
            "elements": [
                "quark:iron_plate@0"
            ]
        },
        {
            "x": 3,
            "y": -3,
            "z": 1,
            "elements": [
                "immersiveengineering:sheetmetal@8"
            ]
        },
        {
            "x": 3,
            "y": 0,
            "z": -2,
            "elements": [
                "quark:iron_plate_stairs@1"
            ]
        },
        {
            "x": 2,
            "y": 0,
            "z": -2,
            "elements": [
                "quark:iron_plate@0"
            ]
        },
        {
            "x": -3,
            "y": 0,
            "z": 2,
            "elements": [
                "quark:iron_plate_stairs@0"
            ]
        },
        {
            "x": 1,
            "y": 0,
            "z": -2,
            "elements": [
                "quark:iron_plate@0"
            ]
        },
        {
            "x": -3,
            "y": -2,
            "z": 1,
            "elements": [
                "immersiveengineering:sheetmetal@8"
            ]
        },
        {
            "x": -2,
            "y": 0,
            "z": 2,
            "elements": [
                "quark:iron_plate@0"
            ]
        },
        {
            "x": 0,
            "y": 0,
            "z": -2,
            "elements": [
                "quark:iron_plate@0"
            ]
        },
        {
            "x": -2,
            "y": -2,
            "z": 1,
            "elements": [
                "thermalfoundation:fluid_aerotheum@0"
            ]
        },
        {
            "x": -1,
            "y": 0,
            "z": 2,
            "elements": [
                "quark:iron_plate@0"
            ]
        },
        {
            "x": -1,
            "y": 0,
            "z": -2,
            "elements": [
                "quark:iron_plate@0"
            ]
        },
        {
            "x": -1,
            "y": -2,
            "z": 1,
            "elements": [
                "thermalfoundation:fluid_aerotheum@0"
            ]
        },
        {
            "x": 0,
            "y": 0,
            "z": 2,
            "elements": [
                "quark:iron_plate@0"
            ]
        },
        {
            "x": -2,
            "y": 0,
            "z": -2,
            "elements": [
                "quark:iron_plate@0"
            ]
        },
        {
            "x": 0,
            "y": -2,
            "z": 1,
            "elements": [
                "thermalfoundation:fluid_aerotheum@0"
            ]
        },
        {
            "x": 1,
            "y": 0,
            "z": 2,
            "elements": [
                "quark:iron_plate@0"
            ]
        },
        {
            "x": -3,
            "y": 0,
            "z": -2,
            "elements": [
                "quark:iron_plate_stairs@0"
            ]
        },
        {
            "x": 1,
            "y": -2,
            "z": 1,
            "elements": [
                "thermalfoundation:fluid_aerotheum@0"
            ]
        },
        {
            "x": 2,
            "y": 0,
            "z": 2,
            "elements": [
                "quark:iron_plate@0"
            ]
        },
        {
            "x": 2,
            "y": -2,
            "z": 1,
            "elements": [
                "thermalfoundation:fluid_aerotheum@0"
            ]
        },
        {
            "x": 3,
            "y": 0,
            "z": 2,
            "elements": [
                "quark:iron_plate_stairs@1"
            ]
        },
        {
            "x": 3,
            "y": -2,
            "z": 1,
            "elements": [
                "immersiveengineering:sheetmetal@8"
            ]
        },
        {
            "x": 3,
            "y": -1,
            "z": -2,
            "elements": [
                "quark:iron_plate@0"
            ]
        },
        {
            "x": 2,
            "y": -1,
            "z": -2,
            "elements": [
                "thermalfoundation:glass@8"
            ]
        },
        {
            "x": 1,
            "y": -1,
            "z": -2,
            "elements": [
                "thermalfoundation:glass@8"
            ]
        },
        {
            "x": -3,
            "y": -1,
            "z": 1,
            "elements": [
                "immersiveengineering:sheetmetal@8"
            ]
        },
        {
            "x": 0,
            "y": -1,
            "z": -2,
            "elements": [
                "thermalfoundation:glass@8"
            ]
        },
        {
            "x": -2,
            "y": -1,
            "z": 1,
            "elements": [
                "thermalfoundation:fluid_aerotheum@0"
            ]
        },
        {
            "x": -1,
            "y": -1,
            "z": -2,
            "elements": [
                "thermalfoundation:glass@8"
            ]
        },
        {
            "x": -1,
            "y": -1,
            "z": 1,
            "elements": [
                "thermalfoundation:fluid_aerotheum@0"
            ]
        },
        {
            "x": -2,
            "y": -1,
            "z": -2,
            "elements": [
                "thermalfoundation:glass@8"
            ]
        },
        {
            "x": 0,
            "y": -1,
            "z": 1,
            "elements": [
                "thermalfoundation:fluid_aerotheum@0"
            ]
        },
        {
            "x": -3,
            "y": -1,
            "z": -2,
            "elements": [
                "quark:iron_plate@0"
            ]
        },
        {
            "x": 1,
            "y": -1,
            "z": 1,
            "elements": [
                "thermalfoundation:fluid_aerotheum@0"
            ]
        },
        {
            "x": 2,
            "y": -1,
            "z": 1,
            "elements": [
                "thermalfoundation:fluid_aerotheum@0"
            ]
        },
        {
            "x": 3,
            "y": -1,
            "z": 1,
            "elements": [
                "immersiveengineering:sheetmetal@8"
            ]
        },
        {
            "x": 3,
            "y": -2,
            "z": -2,
            "elements": [
                "quark:iron_plate@0"
            ]
        },
        {
            "x": 2,
            "y": -2,
            "z": -2,
            "elements": [
                "thermalfoundation:glass@8"
            ]
        },
        {
            "x": 3,
            "y": 0,
            "z": -1,
            "elements": [
                "quark:iron_plate_stairs@1"
            ]
        },
        {
            "x": 1,
            "y": -2,
            "z": -2,
            "elements": [
                "thermalfoundation:glass@8"
            ]
        },
        {
            "x": 2,
            "y": 0,
            "z": -1,
            "elements": [
                "immersiveengineering:sheetmetal@8"
            ]
        },
        {
            "x": -3,
            "y": 0,
            "z": 1,
            "elements": [
                "quark:iron_plate_stairs@0"
            ]
        },
        {
            "x": 0,
            "y": -2,
            "z": -2,
            "elements": [
                "thermalfoundation:glass@8"
            ]
        },
        {
            "x": 1,
            "y": 0,
            "z": -1,
            "elements": [
                "immersiveengineering:sheetmetal@8"
            ]
        },
        {
            "x": -2,
            "y": 0,
            "z": 1,
            "elements": [
                "immersiveengineering:sheetmetal@8"
            ]
        },
        {
            "x": -1,
            "y": -2,
            "z": -2,
            "elements": [
                "thermalfoundation:glass@8"
            ]
        },
        {
            "x": 0,
            "y": 0,
            "z": -1,
            "elements": [
                "immersiveengineering:sheetmetal@8"
            ]
        },
        {
            "x": -1,
            "y": 0,
            "z": 1,
            "elements": [
                "immersiveengineering:sheetmetal@8"
            ]
        },
        {
            "x": -2,
            "y": -2,
            "z": -2,
            "elements": [
                "thermalfoundation:glass@8"
            ]
        },
        {
            "x": -1,
            "y": 0,
            "z": -1,
            "elements": [
                "immersiveengineering:sheetmetal@8"
            ]
        },
        {
            "x": 0,
            "y": 0,
            "z": 1,
            "elements": [
                "immersiveengineering:sheetmetal@8"
            ]
        },
        {
            "x": -3,
            "y": -2,
            "z": -2,
            "elements": [
                "quark:iron_plate@0"
            ]
        },
        {
            "x": -2,
            "y": 0,
            "z": -1,
            "elements": [
                "immersiveengineering:sheetmetal@8"
            ]
        },
        {
            "x": 1,
            "y": 0,
            "z": 1,
            "elements": [
                "immersiveengineering:sheetmetal@8"
            ]
        },
        {
            "x": -3,
            "y": 0,
            "z": -1,
            "elements": [
                "quark:iron_plate_stairs@0"
            ]
        },
        {
            "x": 2,
            "y": 0,
            "z": 1,
            "elements": [
                "immersiveengineering:sheetmetal@8"
            ]
        },
        {
            "x": 3,
            "y": 0,
            "z": 1,
            "elements": [
                "quark:iron_plate_stairs@1"
            ]
        },
        {
            "x": 3,
            "y": -3,
            "z": -2,
            "elements": [
                "quark:iron_plate@0"
            ]
        },
        {
            "x": 2,
            "y": -3,
            "z": -2,
            "elements": [
                "thermalfoundation:glass@8"
            ]
        },
        {
            "x": 3,
            "y": -1,
            "z": -1,
            "elements": [
                "immersiveengineering:sheetmetal@8"
            ]
        },
        {
            "x": 1,
            "y": -3,
            "z": -2,
            "elements": [
                "thermalfoundation:glass@8"
            ]
        },
        {
            "x": 2,
            "y": -1,
            "z": -1,
            "elements": [
                "thermalfoundation:fluid_aerotheum@0"
            ]
        },
        {
            "x": 0,
            "y": -3,
            "z": -2,
            "elements": [
                "thermalfoundation:glass@8"
            ]
        },
        {
            "x": 1,
            "y": -1,
            "z": -1,
            "elements": [
                "thermalfoundation:fluid_aerotheum@0"
            ]
        },
        {
            "x": -1,
            "y": -3,
            "z": -2,
            "elements": [
                "thermalfoundation:glass@8"
            ]
        },
        {
            "x": 0,
            "y": -1,
            "z": -1,
            "elements": [
                "thermalfoundation:fluid_aerotheum@0"
            ]
        },
        {
            "x": -2,
            "y": -3,
            "z": -2,
            "elements": [
                "thermalfoundation:glass@8"
            ]
        },
        {
            "x": -1,
            "y": -1,
            "z": -1,
            "elements": [
                "thermalfoundation:fluid_aerotheum@0"
            ]
        },
        {
            "x": -3,
            "y": -3,
            "z": -2,
            "elements": [
                "quark:iron_plate@0"
            ]
        },
        {
            "x": -2,
            "y": -1,
            "z": -1,
            "elements": [
                "thermalfoundation:fluid_aerotheum@0"
            ]
        },
        {
            "x": -3,
            "y": -1,
            "z": -1,
            "elements": [
                "immersiveengineering:sheetmetal@8"
            ]
        },
        {
            "x": 3,
            "y": -4,
            "z": -2,
            "elements": [
                "quark:iron_plate@0"
            ]
        },
        {
            "x": 2,
            "y": -4,
            "z": -2,
            "elements": [
                "thermalfoundation:glass@8"
            ]
        },
        {
            "x": 3,
            "y": -2,
            "z": -1,
            "elements": [
                "immersiveengineering:sheetmetal@8"
            ]
        },
        {
            "x": 1,
            "y": -4,
            "z": -2,
            "elements": [
                "thermalfoundation:glass@8"
            ]
        },
        {
            "x": 2,
            "y": -2,
            "z": -1,
            "elements": [
                "thermalfoundation:fluid_aerotheum@0"
            ]
        },
        {
            "x": 0,
            "y": -4,
            "z": -2,
            "elements": [
                "thermalfoundation:glass@8"
            ]
        },
        {
            "x": 1,
            "y": -2,
            "z": -1,
            "elements": [
                "thermalfoundation:fluid_aerotheum@0"
            ]
        },
        {
            "x": -1,
            "y": -4,
            "z": -2,
            "elements": [
                "thermalfoundation:glass@8"
            ]
        },
        {
            "x": 0,
            "y": -2,
            "z": -1,
            "elements": [
                "thermalfoundation:fluid_aerotheum@0"
            ]
        },
        {
            "x": -2,
            "y": -4,
            "z": -2,
            "elements": [
                "thermalfoundation:glass@8"
            ]
        },
        {
            "x": -1,
            "y": -2,
            "z": -1,
            "elements": [
                "thermalfoundation:fluid_aerotheum@0"
            ]
        }
    ]}